Workbook

Sheet Banco de dados 
A1: Nome Comercial | B1: Fármaco | C1: Classificação | D1: Sintomatologia | E1: Alterações laboratoriais | F1: Ação com os médicos | G1: Observação | H1: Ação com a Nutrição | I1: ação com a enfermagem
A2: Fluimucil 10% ampola 3ml | B2: Acetilcisteína | C2: Mucolítico | D2: N/A | E2: N/A | F2: N/A | G2: N/A | H2: N/A | I2: N/A
A3: Fluimucil D 600mg granulado | B3: Acetilcisteína | C3: Mucolítico | D3: N/A | E3: N/A | F3: N/A | G3: N/A | H3: N/A | I3: N/A
A4: Diamox 250mg comprimido | B4: Acetazolamida | C4: Diurético e antiglaucoma | D4: Pode causar: anorexia, gosto metálico, diarreía, naúseas, vomoitos, obstipação, boca seca, sonolencia, confusão, fadiga, parestesia Preucação: Lactação,deficiencia de G6PD (risco de anemia hemolítica), insuficiencia renal grave ou doença hepática, | E4: ↓ Na, ↓K, ↑Cl, ↑ácido úrico, ↑glicose (em diabetes),anemias incluindo aplástica fatal rara,discrasias Urina: ↑pH, ↑Na, ↑K, ↓ácido úrico,↑ glicose (em diabetes), ↑tiamina, ↑piridoxina | F4: Monitorar hemograma e plaquetas, eletrólitos, hiperglicemia em diabetes | G4: Com alimentos: Melhora a absorção | H4: Assegurar a ingestão hídrica/hidratação adequada | I4: Administrar junto com as refeições
A5: AAS 100 mg infantil | B5: Acido Acetilsalicílico | C5: Analgésico, anti-inflamatório, antiagregante: | D5: Pode causar: Anorexia, sangramento gástrico ou oral , naúseas, vômito, dispepsia. Evitar: Alcool Precaução: Lactação, Diabetes, não usar em pacientes propensos a deficiência de vitamina K, sangramentos ou gastrite/úlceras Não usar: alergia à tartrazina, anemia grave severa, diminuição da função renal e hepática. | E5: ↓T4, ↓ ou ↑ácido úrico (dose dependente), ↓K, ↑TGO, ↑TGP, ↑fosf alc, ↓Fe, ↑uréia, ↑ creat Urina: ↑vit C, ↑ K ou ↓ glicose (método dependente) | F5: Monitorar Hematocrito e função renal com uso a longo prazo ou em altas doses | G5: Com alimentos ácidos = Aumento da absorção Com alimentos alcalinos = Diminuição da absorção | H5: Equilibrio na ingestão de alimentos capazes de acidificar ou alcalinizar a urina Assegurar ingestão hídrica adequada | I5: Administrar com 1 copo de água ou leite após as refeições ou com alimento
A6: Vitamina C 500mg comprimido | B6: Acido Ascórbico | C6: Vitamina | D6: Pode causar: Naúseas, vômito, dispepsia, cólicas gástricas, diarreia c/>1g/dia | E6: Urina: ↑oxalato, ↑Ca, ↓ Na, ↑ou ↓ác úrico | F6: N/A | G6: N/A | H6: N/A | I6: N/A
A7: Clavulin cp 500mg | B7: Acido clavulanico + Amoxilina | C7: Antibiótico | D7: Pode causar: Diarreia, naúseas, vomitos, glossite, candidíase oral, colite pseudomembranosa, erupções cutaneas, raras reações alergicas (pode ser fatal). Precaução: Lactação | E7: Anemias, discrasias, ↑TGO, ↑TGP | F7: Monitorar função renal, função hépatica e hemograma no uso a longo prazo | G7: Com alimento = Diminui ação do farmaco na mucosa | H7: N/A | I7: Administrar junto com as refeições
A8: Clavulin ampola 500mg | B8: Acido clavulanico + Amoxilina | C8: Antibiótico | D8: Pode causar: Diarreia, naúseas, vomitos, glossite, candidíase oral, colite pseudomembranosa, erupções cutaneas, raras reações alergicas (pode ser fatal). Precaução: Lactação | E8: Anemias, discrasias, ↑TGO, ↑TGP | F8: Monitorar função renal, função hépatica e hemograma no uso a longo prazo | G8: Com alimento = Diminui ação do farmaco na mucosa | H8: N/A | I8: Administrar junto com as refeições
A9: Endofolin 5mg comprimido | B9: Ácido Fólico | C9: Vitamina | D9: Condições especiais: Não usar com anemia perniciosa não tratada | E9: ↓ vit B12, c/altas doses a longo prazo, ↓ homocisteína, ↑erit, ↑leuc, ↑plaquetas, ↑Hb, ↑Hct, ↓HGM, ↓ VGM quando usado para tratar anemia | F9: Monitorar Hemograma, Vitamina B12 c/altas doses a longo prazo | G9: Com alimentos ricos em Zn = Diminui a absorção | H9: Dieta balanceada Tomar suplemento de Zn separadamente por 2 horas | I9: N/A
A10: Transamin ampola 5ml | B10: Ácido Tranexâmico | C10: Hemostático | D10: N/A | E10: N/A | F10: N/A | G10: N/A | H10: N/A | I10: N/A
A11: Depakene 500mg comprimido | B11: Ácido Valproico | C11: Anticonvulsivante | D11: N/A | E11: N/A | F11: N/A | G11: N/A | H11: N/A | I11: N/A
A12: Adenocard 3mg/ml ampola 2ml | B12: Adenosina | C12: Antiarrítmico | D12: N/A | E12: N/A | F12: N/A | G12: alimentos que possuem cafeina e teofilina, pois pode reduzir a resposta cardiovascular. | H12: Evitar alientos como café e a base de chocolate. | I12: N/A
... A34: Zitromax ampola | B34: Azitromicina | C34: Antibiótico | D34: Pode causar: Estomatite, diarreia, dor abdominal Precaução: Lactação, ↓função renal ou hepatica | E34: ↑ CPK, ↑TGO, ↑TGP, ↑GGT, ↑K | F34: Monitorar função hepática com usooral a longo prazo | G34: N/A | H34: N/A | I34: Tomar 1h antes ou 2h após as refeições. Tomar junto com as refeições em caso de desconforto GI
A35: Azul de metileno 4% | C35: Antídoto | D35: N/A | E35: N/A | F35: N/A | G35: N/A | H35: N/A | I35: N/A
A36: lioresal 10mg comprimido | B36: Baclofeno | C36: Relaxante muscular | D36: Pode causar: Boca seca, nauseas, vomito, alterações de paladar, obstipação, sonolência, tontura, fraqueza, confusão, cefaleia, depressão, insônia, ↓PA, edema Precaução: Alccol, não usar ↓função renal, | E36: ↑fosf alc, ↑TGO, ↑TGP, ↑glicose Urina: ↑frequencia , retenção | F36: N/A | G36: N/A | H36: N/A | I36: N/A
A37: Bamifix 600mg | B37: Bamifilina | C37: Broncodilatador | D37: N/A | E37: N/A | F37: N/A | G37: N/A | H37: N/A | I37: N/A
A38: Benzetacil 600.000 UI Benzetacil1200000 UI | B38: Benzilpenicilina | C38: Antibiótico | D38: Pode causar: Anorexia, Precaução: não usar ↓função renal, lactação | E38: Discrasias, ↑K ( especialmente pen GK, ↑Na (pen G Na) Urina: +p/glicose ou falso ↑esteroídes (método-dependente) c/pen G | F38: Em uso a longo prazo ou altas doses: hemograma, função renal, eletrolitos, K ou Na especialmente c/pen G | G38: Com suplementos de K c/pen - VK | H38: N/A | I38: Tomar 1 hora antes ou 2 horas antes da alimentação, em caso de desconforto tomar junto com o alimento
A39: Despacilina 400.000 UI | B39: Benzilpenicilina potássica + Benzilpenicilina procaína | C39: Antibiótico | D39: Pode causar: Anorexia, Precaução: não usar ↓função renal, lactação | E39: Discrasias, ↑K ( especialmente pen GK, ↑Na (pen G Na) Urina: +p/glicose ou falso ↑esteroídes (método-dependente) c/pen G | F39: Em uso a longo prazo ou altas doses: hemograma, função renal, eletrolitos, K ou Na especialmente c/pen G | G39: Com suplementos de K c/pen - VK | H39: N/A | I39: Tomar 1 hora antes ou 2 horas antes da alimentação, em caso de desconforto tomar junto com o alimento
A40: Celestone Soluspan | B40: Fosfato de Betametasona | C40: Anti-inflamatorio Esteroidal | D40: Pode causar: Anorexia, naúseas, vomitos, dispesia, úldera péptica, flatulência, sangramento/perfuração GI, ↑apetite, ↑peso, anorexia, osteporose e necrose a longo prazo, ↑ necessidade de folato, edema, insônia, hematomas, cicatrização lenta Precaução: Alccol, não usar na lactação, diabetes (↑glicemia), hipoalbuminemia (<3g/dl) pode ↑efeitos do fármaco, ↓função renal ou epilepsia | E40: ↑Na, ↓K, ↑Ca, ↑glicose, ↓Zn, ↓ác úrico, ↓vit C, ↓Vit A, ↑Tg, ↑Col, ↓T3, ↓T4, ↓TSH, ↑Hb, ↑erit, discrasias | F40: A longo prazo: Eletrolitos, glicemia, PA, peso, crescimento em crianças, densidade óssea c/uso >2 meses, função adrenal | G40: ↓Na, ↑Ca, ↑vit D, ↑ptn. Pode necessitar , ↑ K, ↑vit Ae C, ↑P(ou suplementação). Suplementação de Ca e Vit D recomendada c/uso a longo prazo. | H40: N/A | I40: Tomar junto com o alimento para diminuir os sintomas
A41: Bicarbonato de sódio 8,4% 10 ml | C41: Solução hidroeletrolitica | D41: Pode causar: ↑ sede, ↑ peso (edema), distensão gástrica,cólicas, flatulência Precaução: ↓função renal, ICC, HÁ | E41: ↑ Na, ↓K, ↓Ca Urina ↑ph | F41: N/A | G41: N/A | H41: Considerar conteúdo de Na, com dietas ↓Na. Precaução c/suplemento de Ca ou ingestão elevada de leite c/uso a longo prazo | I41: Como antiácido: Tomar após as refeições. Tomar suplemento de Fe separadamente 1 hora antes ou 2 horas após a administração do fármaco
A42: Bicarbonato de sódio 8,4%250 ml) | C42: Solução hidroeletrolitica | D42: Pode causar: ↑ sede, ↑ peso (edema), distensão gástrica,cólicas, flatulência Precaução: ↓função renal, ICC, HÁ | E42: ↑ Na, ↓K, ↓Ca Urina ↑ph | F42: N/A | G42: N/A | H42: Considerar conteúdo de Na, com dietas ↓Na. Precaução c/suplemento de Ca ou ingestão elevada de leite c/uso a longo prazo | I42: Como antiácido: Tomar após as refeições. Tomar suplemento de Fe separadamente 1 hora antes ou 2 horas após a administração do fármaco
A43: Dulcolax comprimido | B43: Bisacodil | C43: Laxante | D43: Pode causar: naúseas, diarreia, dor abdominal, eructação. Uso a longo prazo: dependencia laxativa, má absorção e esteatorreia Precaução: Não usar na lactação | E43: a longo prazo ↓K, ↓Ca | F43: N/A | G43: N/A | H43: Dieta rica em fibra e ingestão hidrica de 1,5 - 2 l/ao dia | I43: Tomar a tarde com o estomago vazio com 1 copo de água ou suco. Engolir inteiro o comprimido, não triturar. Obsevar intervalo de 1 hora entra a ingestão do fármaco e e de leite.
A44: Lexotan 3mg comprimido | B44: Bromazepan | C44: Ansiolítico/hipnótico | D44: N/A | E44: N/A | F44: N/A | G44: N/A | H44: N/A | I44: N/A
A45: Atrovent 0,025% frasco 10ml | B45: Brometo de Ipratropio | C45: Broncodilatador | D45: Pode causar: Garganta/boca seca, paladar metalico/amargo, naúseas, dispesia, tosse, cefaleia, dispneia, tontura, disturbios visuais, palpitações, dor nas costas ou peito, palpitações , retenção urinaria Precaução: Lactação | E45: N/A | F45: N/A | G45: N/A | H45: N/A | I45: N/A
A47: Digesan injetável | B47: Bromoprida | C47: Antiemético/procinético | D47: N/A | E47: N/A | F47: N/A | G47: N/A | H47: N/A | I47: N/A
A48: Digesan comprimido 10mg | B48: Bromoprida | C48: Antiemético/procinético | D48: N/A | E48: N/A | F48: N/A | G48: N/A | H48: N/A | I48: N/A
A49: Pulmicort 0,25mg/ml | B49: Budesonida | C49: Antiinflamatorio esteroidal | D49: N/A | E49: N/A | F49: N/A | G49: N/A | H49: N/A | I49: N/A
A50: Oscal D comprimido | B50: Carbonato de Calcio+ colecalciferol | C50: Suplemento Mineral | D50: Pode causar: ↑ abs de Ca, anorexia, ↓ peso, ↑sede. Sintomas de def: raquitismo, crecimento, palpitações, irritabilidade, boca seca, paladar metalico, nauseas, vomito, obstipação, diarreia. Precaução: Não usar em hiperglicemia ou hiperfostemia, ↓função renal ou cardiaca | E50: ↑ Ca, ↑P, ↓fosf alc,↑ Mg, ↑ ureia, ↑creat, ↑TGO, ↑tgp, ↑COL. Hipercalcemia induzida por ergocalciferol persiste mais tempo do que c/o calcitriol. Urina: ↑Ca c/vit D > 60ug, ↑P, ↑alb, poliuria | F50: Ca, P, função renal | G50: N/A | H50: N/A | I50: Pode ser adm diretamente na boca ou misturada c/alimentos moles ou suco
A51: Atacand 16mg | B51: Candesartana | C51: anti-hipertensivo | D51: N/A | E51: N/A | F51: N/A | G51: Alimentos com alto teor de potassio pode interferir na absorção do farmaco. | H51: Evitar alimentos com essas caracteristicas. | I51: N/A
A52: Capoten 25mg | B52: Captopril | C52: Anti-hipertensivo | D52: Pode causar: anorexia, ↓peso, Fe, Mg, Al: ↓ abs do farmaco, paladar metalico ou salgado, nauseas, vomitos, úlcera peptica, dor abdominal, obstipação, diarreia, ↓ PA, c/possivel hipotensão, tosse Precaução: Diabetes, ↓glicemia | E52: ↓ leuc ou discrasias, ↑ K, ↓Na, ↑TGO, ↑TGP, ↑fosf alc, ↑bil, ↑ prolactina, ↑ác úrico, ↓ glicose em DM, transitorio ↑ureia, ↑Creat Urina: ptn, Zn | F52: PA, eletrolitos, função renal, leucograma, glicemia para DM | G52: Com alimento: Diminui a absorção do fármaco. deve evitar a ingestão de alimentos ricos em potássio na dieta. | H52: Assegurar a ingestão hidrica/hidratação adequada, ↓Na, ↓cal pode ser recomendada. Evitar substitutos do sal. Precaução c/ Fe ou Mg/antiácidos separadamente por pelo menos 2h | I52: Tomar c/ estomago vazio 1 hora das refeições
A53: Tegretol 200mg comprimido | B53: Carbamazepina | C53: Anticonvulsivante | D53: Pode causar: Anorexia,↓folato, ↓vit D, nauseas, vomito, boca seca, estomatite, glossite, dor abdominal, obstipação, diarreia, tontura, edema, disturbios visuais, sonolencia, ataxia, tontura Precaução: Alcool , não uxar na lactação, ↑ risco de problemas dentários, ↓função hepatico | E53: ↓ leuc, ↓folato, ↓Ca, discrasias, ↓T3, ↓T4, ↓Na, ↓biotina, ↑ureia, ↑TGO, ↑TGP, ↑fosf alc, ↑bile, ↑TG | F53: Monitora niveis do farmaco, exames oculares, , hemograma, função renal e hepatica, Fe, Ca, Na séricos, urinálise. | G53: Com alimento ricos em gordura= Aumenta a Consumo de Toranja = Aumenta a absorção | H53: Incentivar o consumo de gordura de forma equilibrada no horário de administração do fármaco Dieta isenta de toranja * Verificar os niveis de sódio no organismo em tratamentos prolongados | I53: Administrar junto com a refeição ou logo após
A54: Carvão ativado pó 50 gr | C54: Antídoto | D54: N/A | E54: N/A | F54: N/A | G54: N/A | H54: N/A | I54: N/A
A55: Cardilol 3,125 | B55: Carvedilol | C55: Anti-hipertensivo | D55: N/A | E55: N/A | F55: N/A | G55: N/A | H55: N/A | I55: N/A
A56: Keflex 500mg comprimido | B56: Cefalexina | C56: Antibiótico | D56: Pode causar: Candidiase oral, inflamação da mucosa bucal e língua em uso a longo prazo, dispseia, gastrite, diarreia, colite pseudomembranosa. Precaução: Lactação, ↓função renal | E56: ↑TGO, ↑TGP, eosinofilia, ↓leuc, ↑ureia, ↑creat, falso para p/Coombs | F56: N/A | G56: N/A | H56: N/A | I56: Tomar sem considrar a alimentação
A57: Keflin 1 g frasco | B57: Cafalotina | C57: Antibiótico | D57: Pode causar: Não usar com alcool c/ cefoperazona (reação semelhante ao dissulfiram). Precaução: Lactação. Uso a longo prazo em desnutridos: ↓sintese de vit K,↓função renal | E57: Discrasias, eosinofilia. Transitorio: ↑TGO, ↑ TGP, ↑fosf alc, ↑GGT, ↑LD, ↑ureia, ↑creat | F57: Monitorar TP, hemograma completo se usado mais de 10 dias | G57: N/A | H57: Considerar conteúdo de Na, com dietas ↓Na. Pode necessitar de ↑K ou suplemento, especialmente cefopeparozona para prevenir sangramento devido à hipoprotrombinemia | I57: Compativel c/NP
A58: Kefazol 1gr frasco | B58: Cefazolina | C58: Antibiótico | D58: Pode causar: Não usar com alcool c/ cefoperazona (reação semelhante ao dissulfiram). Precaução: Lactação. Uso a longo prazo em desnutridos: ↓sintese de vit K,↓função renal | E58: Discrasias, eosinofilia. Transitorio: ↑TGO, ↑ TGP, ↑fosf alc, ↑GGT, ↑LD, ↑ureia, ↑creat | F58: Monitorar TP, hemograma completo se usado mais de 10 dias | G58: N/A | H58: Considerar conteúdo de Na, com dietas ↓Na. Pode necessitar de ↑K ou suplemento, especialmente cefopeparozona para prevenir sangramento devido à hipoprotrombinemia | I58: Compativel c/NP
A60: Maxcef 1g | B60: Cefepima | C60: Antibiótico | D60: Pode causar: Não usar com alcool c/ cefoperazona (reação semelhante ao dissulfiram). Precaução: Lactação. Uso a longo prazo em desnutridos: ↓sintese de vit K,↓função renal | E60: Discrasias, eosinofilia. Transitorio: ↑TGO, ↑ TGP, ↑fosf alc, ↑GGT, ↑LD, ↑ureia, ↑creat | F60: Monitorar TP, hemograma completo se usado mais de 10 dias | G60: N/A | H60: Considerar conteúdo de Na, com dietas ↓Na. Pode necessitar de ↑K ou suplemento, especialmente cefopeparozona para prevenir sangramento devido à hipoprotrombinemia | I60: Compativel c/NP
A61: Fortaz 1gr | B61: Ceftazidima | C61: Antibiótico | D61: Pode causar: Não usar com alcool c/ cefoperazona (reação semelhante ao dissulfiram). Precaução: Lactação. Uso a longo prazo em desnutridos: ↓sintese de vit K,↓função renal | E61: Discrasias, eosinofilia. Transitorio: ↑TGO, ↑ TGP, ↑fosf alc, ↑GGT, ↑LD, ↑ureia, ↑creat | F61: Monitorar TP, hemograma completo se usado mais de 10 dias | G61: N/A | H61: Considerar conteúdo de Na, com dietas ↓Na. Pode necessitar de ↑K ou suplemento, especialmente cefopeparozona para prevenir sangramento devido à hipoprotrombinemia | I61: Compativel c/NP
A62: Rocefin 1gr | B62: Ceftriaxona | C62: Antibiótico | D62: Pode causar: Não usar com alcool c/ cefoperazona (reação semelhante ao dissulfiram). Precaução: Lactação. Uso a longo prazo em desnutridos: ↓sintese de vit K,↓função renal | E62: Discrasias, eosinofilia. Transitorio: ↑TGO, ↑ TGP, ↑fosf alc, ↑GGT, ↑LD, ↑ureia, ↑creat | F62: Monitorar TP, hemograma completo se usado mais de 10 dias | G62: N/A | H62: Considerar conteúdo de Na, com dietas ↓Na. Pode necessitar de ↑K ou suplemento, especialmente cefopeparozona para prevenir sangramento devido à hipoprotrombinemia | I62: Compativel c/NP
A63: Zinacef 750 | B63: cefuroxima | C63: Antibiótico | D63: Pode causar: Paladar amargo, nausea, diarreia, candidiase oral e inflamação da mucosa bucal e lingua a longo prazo. Precaução: não usar na lactação, ↓função renal | E63: ↑incidencia c/parenteral, ↓HB, ↓Hct, eosinofilia, ↑TGO, ↑TGP, ↑fosf alc, ↑LDL | F63: N/A | G63: Com alimento = Aumenta a absorção | H63: N/A | I63: Administrar junto com a refeição
...

Sheet Avaliação
C1: AVALIAÇÃO - INTERAÇÃO DROGA NUTRIENTE
A3: Nome do paciente:
A4: Registro:
A5: Data de nascimento:
A6: Idade | C6: =INT(C8-C5)/365.25 -> 0
A7: Data da prescrição: | E7: =TEXT(C7,"dddd") -> sábado
A8: Data da avaliação: | E8: =TEXT(C8,"dddd") -> sábado
A9: Farmaceutica Responsavél:
A11: Nome Comercial | B11: Fármaco | C11: Alterações laboratoriais | D11: Sintomatologia | E11: Nutrição | F11: Enfermagem | G11: Médica
B12: =IFERROR(VLOOKUP(A12,'Banco de dados '!1:1048576,2,FALSE),"") | C12: =IFERROR(VLOOKUP(A12,'Banco de dados '!1:1048576,2,FALSE),"") | D12: =IFERROR(VLOOKUP(A12,'Banco de dados '!1:1048576,4,FALSE),"") | E12: =IFERROR(VLOOKUP(A12,'Banco de dados '!1:1048576,8,FALSE),"") | F12: =IFERROR(VLOOKUP(A12,'Banco de dados '!1:1048576,7,FALSE),"") | G12: =IFERROR(VLOOKUP(A12,'Banco de dados '!1:1048576,6,FALSE),"")
B13: =IFERROR(VLOOKUP(A13,'Banco de dados '!1:1048576,2,FALSE),"") | C13: =IFERROR(VLOOKUP(A13,'Banco de dados '!1:1048576,2,FALSE),"") | D13: =IFERROR(VLOOKUP(A13,'Banco de dados '!1:1048576,4,FALSE),"") | E13: =IFERROR(VLOOKUP(A13,'Banco de dados '!1:1048576,8,FALSE),"") | F13: =IFERROR(VLOOKUP(A13,'Banco de dados '!1:1048576,7,FALSE),"") | G13: =IFERROR(VLOOKUP(A13,'Banco de dados '!1:1048576,6,FALSE),"")
B14: =IFERROR(VLOOKUP(A14,'Banco de dados '!1:1048576,2,FALSE),"") | C14: =IFERROR(VLOOKUP(A14,'Banco de dados '!1:1048576,2,FALSE),"") | D14: =IFERROR(VLOOKUP(A14,'Banco de dados '!1:1048576,4,FALSE),"") | E14: =IFERROR(VLOOKUP(A14,'Banco de dados '!1:1048576,8,FALSE),"") | F14: =IFERROR(VLOOKUP(A14,'Banco de dados '!1:1048576,7,FALSE),"") | G14: =IFERROR(VLOOKUP(A14,'Banco de dados '!1:1048576,6,FALSE),"")
B15: =IFERROR(VLOOKUP(A15,'Banco de dados '!1:1048576,2,FALSE),"") | C15: =IFERROR(VLOOKUP(A15,'Banco de dados '!1:1048576,2,FALSE),"") | D15: =IFERROR(VLOOKUP(A15,'Banco de dados '!1:1048576,4,FALSE),"") | E15: =IFERROR(VLOOKUP(A15,'Banco de dados '!1:1048576,8,FALSE),"") | F15: =IFERROR(VLOOKUP(A15,'Banco de dados '!1:1048576,7,FALSE),"") | G15: =IFERROR(VLOOKUP(A15,'Banco de dados '!1:1048576,6,FALSE),"")
B16: =IFERROR(VLOOKUP(A16,'Banco de dados '!1:1048576,2,FALSE),"") | C16: =IFERROR(VLOOKUP(A16,'Banco de dados '!1:1048576,2,FALSE),"") | D16: =IFERROR(VLOOKUP(A16,'Banco de dados '!1:1048576,4,FALSE),"") | E16: =IFERROR(VLOOKUP(A16,'Banco de dados '!1:1048576,8,FALSE),"") | F16: =IFERROR(VLOOKUP(A16,'Banco de dados '!1:1048576,7,FALSE),"") | G16: =IFERROR(VLOOKUP(A16,'Banco de dados '!1:1048576,6,FALSE),"")
B17: =IFERROR(VLOOKUP(A17,'Banco de dados '!1:1048576,2,FALSE),"") | C17: =IFERROR(VLOOKUP(A17,'Banco de dados '!1:1048576,2,FALSE),"") | D17: =IFERROR(VLOOKUP(A17,'Banco de dados '!1:1048576,4,FALSE),"") | E17: =IFERROR(VLOOKUP(A17,'Banco de dados '!1:1048576,8,FALSE),"") | F17: =IFERROR(VLOOKUP(A17,'Banco de dados '!1:1048576,7,FALSE),"") | G17: =IFERROR(VLOOKUP(A17,'Banco de dados '!1:1048576,6,FALSE),"")
B18: =IFERROR(VLOOKUP(A18,'Banco de dados '!1:1048576,2,FALSE),"") | C18: =IFERROR(VLOOKUP(A18,'Banco de dados '!1:1048576,2,FALSE),"") | D18: =IFERROR(VLOOKUP(A18,'Banco de dados '!1:1048576,4,FALSE),"") | E18: =IFERROR(VLOOKUP(A18,'Banco de dados '!1:1048576,8,FALSE),"") | F18: =IFERROR(VLOOKUP(A18,'Banco de dados '!1:1048576,7,FALSE),"") | G18: =IFERROR(VLOOKUP(A18,'Banco de dados '!1:1048576,6,FALSE),"")
B19: =IFERROR(VLOOKUP(A19,'Banco de dados '!1:1048576,2,FALSE),"") | C19: =IFERROR(VLOOKUP(A19,'Banco de dados '!1:1048576,2,FALSE),"") | D19: =IFERROR(VLOOKUP(A19,'Banco de dados '!1:1048576,4,FALSE),"") | E19: =IFERROR(VLOOKUP(A19,'Banco de dados '!1:1048576,8,FALSE),"") | F19: =IFERROR(VLOOKUP(A19,'Banco de dados '!1:1048576,7,FALSE),"") | G19: =IFERROR(VLOOKUP(A19,'Banco de dados '!1:1048576,6,FALSE),"")
B20: =IFERROR(VLOOKUP(A20,'Banco de dados '!1:1048576,2,FALSE),"") | C20: =IFERROR(VLOOKUP(A20,'Banco de dados '!1:1048576,2,FALSE),"") | D20: =IFERROR(VLOOKUP(A20,'Banco de dados '!1:1048576,4,FALSE),"") | E20: =IFERROR(VLOOKUP(A20,'Banco de dados '!1:1048576,8,FALSE),"") | F20: =IFERROR(VLOOKUP(A20,'Banco de dados '!1:1048576,7,FALSE),"") | G20: =IFERROR(VLOOKUP(A20,'Banco de dados '!1:1048576,6,FALSE),"")
A21: Conduta Final:

Sheet Rereferncias
A1: REFERÊNCIAS:1 - lacy CF, Armstrong ll, Goldman MP, lance ll. Drug information handbook. 2010-2011. Hudson: lexi-Comp; 2010 2 Micromedex. Healthcare series, [base de dados Internet]. Greenwood Village: Thomson MICROMEDEX; 2009 [acesso em 05.2010]. Disponível em URl: http://www.micromedex.com/products/drugdex. 3 - Bula do medicamento. Site ANVISA. 4 - lopes EM, Carvalho RBN, Freitas RM. Análise das possíveis interações entre medicamentos e alimentojnutrientes em pacientes hospitalizados. Einstein. 2010; 8(3 Pt 1):298-302.
